Workbook

Sheet Assumptions
A1: SOVEREIGN MISFIT FARM — FINANCIAL MODEL
A2: Key Assumptions & Inputs
A4: Assumption | B4: Conservative | C4: Moderate | D4: Optimistic | E4: Unit | F4: Notes
A5: LAND & DEVELOPMENT
A6: Total Acreage | B6: 50 | C6: 50 | D6: 50 | E6: acres | F6: Target property size
A7: Land Purchase Price | B7: 250000 | C7: 200000 | D7: 150000 | E7: $ | F7: Rural land, varies by state
A8: Land Price per Acre | B8: =B7/B6 -> 5000 | C8: =C7/C6 -> 4000 | D8: =D7/D6 -> 3000 | E8: $/acre | F8: Formula: total / acres
A9: Site Development Cost | B9: 350000 | C9: 300000 | D9: 250000 | E9: $ | F9: Roads, well, septic, electric run
A10: Community Hall Build Cost | B10: 400000 | C10: 350000 | D10: 300000 | E10: $ | F10: Hexagonal timber-frame, kitchen, bathrooms
A11: Infrastructure Total | B11: =B7+B9+B10 -> 1000000 | C11: =C7+C9+C10 -> 850000 | D11: =D7+D9+D10 -> 700000 | E11: $ | F11: Land + site dev + hall
A12: Contingency Rate | B12: 0.15 | C12: 0.1 | D12: 0.08 | E12: % | F12: % of infrastructure total
A13: Total Startup Capital Needed | B13: =B11*(1+B12) -> 1150000 | C13: =C11*(1+C12) -> 935000 | D13: =D11*(1+D12) -> 756000 | E13: $ | F13: Infrastructure + contingency
A15: HOUSEHOLD & GROUND LEASE
A16: Total Home Sites | B16: 12 | C16: 12 | D16: 12 | E16: # | F16: Max households
A17: Avg Home Build Cost (by resident) | B17: 45000 | C17: 55000 | D17: 65000 | E17: $ | F17: Resident-funded; tiny/alt builds
A18: Monthly Ground Lease Fee (Year 1) | B18: 450 | C18: 500 | D18: 550 | E18: $/mo | F18: Per household, covers land + shared services
A19: Annual Ground Lease Escalation | B19: 0.02 | C19: 0.025 | D19: 0.03 | E19: % | F19: Annual increase rate
A20: Year 1 Occupied Homes | B20: 4 | C20: 5 | D20: 6 | E20: # | F20: Initial move-ins
A21: Year 2 Occupied Homes | B21: 7 | C21: 8 | D21: 9 | E21: #
A22: Year 3 Occupied Homes | B22: 9 | C22: 10 | D22: 11 | E22: #
A23: Year 4+ Occupied Homes | B23: 11 | C23: 12 | D23: 12 | E23: # | F23: Stabilized occupancy
A24: Vacancy/Turnover Rate (stabilized) | B24: 0.05 | C24: 0.03 | D24: 0.02 | E24: % | F24: Expected ongoing vacancy
A26: AGRICULTURAL REVENUE
A27: CSA Shares - Year 1 Members | B27: 20 | C27: 30 | D27: 40 | E27: # | F27: Community Supported Agriculture
A28: CSA Shares - Stabilized Members | B28: 50 | C28: 75 | D28: 100 | E28: # | F28: Full subscription capacity
A29: CSA Share Price (annual) | B29: 600 | C29: 650 | D29: 700 | E29: $ | F29: 26-week season @ ~$25/week
A30: CSA Annual Price Increase | B30: 0.03 | C30: 0.03 | D30: 0.04 | E30: %
A31: Farm Stand Weekly Revenue (peak) | B31: 400 | C31: 600 | D31: 800 | E31: $/wk | F31: 20-week season
A32: Farm Stand Growth Rate | B32: 0.05 | C32: 0.08 | D32: 0.1 | E32: % | F32: Annual growth after Year 1
A33: Farm Stand Weeks per Year | B33: 20 | C33: 24 | D33: 28 | E33: # | F33: Seasonal
A34: Value-Added Products (Year 1) | B34: 3000 | C34: 5000 | D34: 8000 | E34: $/yr | F34: Honey, preserves, soap, herbal
A35: Value-Added Growth Rate | B35: 0.1 | C35: 0.15 | D35: 0.2 | E35: % | F35: Annual growth
A37: WORKSHOPS & AGRITOURISM
A38: Workshops per Year (Year 1) | B38: 6 | C38: 10 | D38: 15 | E38: # | F38: Natural building, fermentation, etc.
A39: Workshops per Year (Stabilized) | B39: 18 | C39: 24 | D39: 36 | E39: #
A40: Avg Workshop Attendees | B40: 10 | C40: 12 | D40: 15 | E40: #
A41: Avg Workshop Ticket Price | B41: 50 | C41: 65 | D41: 75 | E41: $
A42: Workshop Price Annual Increase | B42: 0.02 | C42: 0.03 | D42: 0.03 | E42: %
A43: Farm Tour Revenue (Year 1) | B43: 1000 | C43: 2000 | D43: 3000 | E43: $/yr | F43: School groups, agritourism
A44: Farm Tour Growth Rate | B44: 0.1 | C44: 0.15 | D44: 0.2 | E44: %
...

Sheet Capital Stack
A1: SOVEREIGN MISFIT FARM — CAPITAL STACK
A2: Layered Funding Strategy by Source and Phase
A4: Funding Source | B4: Conservative | C4: Moderate | D4: Optimistic | E4: Type | F4: Terms & Notes
A5: DEBT INSTRUMENTS
A6: CDFI Land Acquisition Loan | B6: =Assumptions!B76 -> 250000 | C6: =Assumptions!C76 -> 200000 | D6: =Assumptions!D76 -> 150000 | E6: Senior Debt | F6: 20-30yr term, 3.5-5.5% fixed, secured by land
A7: Annual Payment | B7: =Assumptions!B79 -> 20919.833 | C7: =Assumptions!C79 -> 13487.806 | D7: =Assumptions!D79 -> 8155.6997 | F7: PMT calculation
A8: Community Investment Notes | B8: =Assumptions!B88 -> 50000 | C8: =Assumptions!C88 -> 75000 | D8: =Assumptions!D88 -> 100000 | E8: Mezzanine | F8: 3-5yr term, 4% fixed, unsecured; impact investors
A9: Annual Interest | B9: =Assumptions!B97 -> 2000 | C9: =Assumptions!C97 -> 3000 | D9: =Assumptions!D97 -> 4000 | F9: Interest-only, balloon at maturity
A10: Total Debt | B10: =B6+B8 -> 300000 | C10: =C6+C8 -> 275000 | D10: =D6+D8 -> 250000
A12: GRANTS & SUBSIDIES (NON-DILUTIVE)
A13: Conservation Easement Sale | B13: =Assumptions!B81 -> 60000 | C13: =Assumptions!C81 -> 100000 | D13: =Assumptions!D81 -> 150000 | E13: Asset Sale | F13: Sell ag easement to state/land trust; $2-3K/acre
A14: State Housing Trust Fund | B14: =Assumptions!B82 -> 0 | C14: =Assumptions!C82 -> 50000 | D14: =Assumptions!D82 -> 100000 | E14: Forgivable | F14: Converts to grant if affordable 30+ yrs
A15: USDA EQIP Grants | B15: =Assumptions!B83 -> 15000 | C15: =Assumptions!C83 -> 30000 | D15: =Assumptions!D83 -> 50000 | E15: Grant | F15: Conservation practices: fencing, cover crops, water
A16: USDA Rural Development | B16: =Assumptions!B84 -> 0 | C16: =Assumptions!C84 -> 25000 | D16: =Assumptions!D84 -> 50000 | E16: Grant | F16: Community Facilities program for hall
A17: Total Grants & Subsidies | B17: =SUM(B13:B16) -> 75000 | C17: =SUM(C13:C16) -> 205000 | D17: =SUM(D13:D16) -> 350000
A19: COMMUNITY EQUITY & CONTRIBUTIONS
A20: Founding Member Deposits | B20: =Assumptions!B85 -> 20000 | C20: =Assumptions!C85 -> 37500 | D20: =Assumptions!D85 -> 60000 | E20: Equity | F20: Refundable on exit per ground lease
A21: Crowdfunding & Donations | B21: =Assumptions!B89 -> 10000 | C21: =Assumptions!C89 -> 25000 | D21: =Assumptions!D89 -> 50000 | E21: Donation | F21: Tax-deductible to 501(c)(3)
A22: Total Community Equity | B22: =B20+B21 -> 30000 | C22: =C20+C21 -> 62500 | D22: =D20+D21 -> 110000
A24: TOTAL CAPITAL STACK
A25: Total Funding Available | B25: =B10+B17+B22 -> 405000 | C25: =C10+C17+C22 -> 542500 | D25: =D10+D17+D22 -> 710000 | F25: All sources
A26: Total Capital Required | B26: =Assumptions!B73 -> 695000 | C26: =Assumptions!C73 -> 562000 | D26: =Assumptions!D73 -> 430000 | F26: All phases
A27: Net Position (Surplus / Gap) | B27: =B25-B26 -> -290000 | C27: =C25-C26 -> -19500 | D27: =D25-D26 -> 280000 | F27: Must be positive
A29: FUNDING MIX (% of Total)
A30: Debt % | B30: =IF(B25=0,0,B10/B25) -> 0.74074074 | C30: =IF(C25=0,0,C10/C25) -> 0.50691244 | D30: =IF(D25=0,0,D10/D25) -> 0.35211268
A31: Grants & Subsidies % | B31: =IF(B25=0,0,B17/B25) -> 0.18518519 | C31: =IF(C25=0,0,C17/C25) -> 0.37788018 | D31: =IF(D25=0,0,D17/D25) -> 0.49295775
A32: Community Equity % | B32: =IF(B25=0,0,B22/B25) -> 0.074074074 | C32: =IF(C25=0,0,C22/C25) -> 0.11520737 | D32: =IF(D25=0,0,D22/D25) -> 0.15492958
A34: SAFETY METRICS
A35: Max Single Source as % of Total | B35: =MAX(B30:B32) -> 0.74074074 | C35: =MAX(C30:C32) -> 0.50691244 | D35: =MAX(D30:D32) -> 0.49295775 | F35: Target: <70% from any single source
A36: Debt-to-Total Capital Ratio | B36: =B30 -> 0.74074074 | C36: =C30 -> 0.50691244 | D36: =D30 -> 0.35211268 | F36: Target: <60% for lender comfort
A37: Annual Debt Service | B37: =Assumptions!B98 -> 22919.833 | C37: =Assumptions!C98 -> 16487.806 | D37: =Assumptions!D98 -> 12155.7 | F37: Lower = safer; reduced by grant layer
A38: Grant Funding as % of Total | B38: =B31 -> 0.18518519 | C38: =C31 -> 0.37788018 | D38: =D31 -> 0.49295775 | F38: Higher = less debt burden

Sheet Farmer Legacy
A1: FARMER LEGACY PIPELINE
A2: Improved Farmland vs. Raw Land — Side-by-Side Comparison
A4: Cost Category | B4: Raw Land (Base Model) | C4: Improved Farmland | D4: Savings / Difference | E4: Notes
A5: LAND ACQUISITION
A6: Acreage | B6: 50 | C6: 50 | E6: Same target size
A7: Price per Acre | B7: 4000 | C7: 5500 | D7: =B7-C7 -> -1500 | E7: Improved land costs more per acre
A8: Land Purchase Price | B8: =B6*B7 -> 200000 | C8: =C6*C7 -> 275000
A10: EXISTING INFRASTRUCTURE (included in improved price)
A11: Well (already drilled) | B11: 15000 | C11: 0 | D11: =B11-C11 -> 15000 | E11: Existing well saves $10-15K
A12: Road access (already graded) | B12: 20000 | C12: 0 | D12: =B12-C12 -> 20000 | E12: Farm roads already in place
A13: Electrical service (already run) | B13: 25000 | C13: 0 | D13: =B13-C13 -> 25000 | E13: Power already on-site
A14: Perimeter fencing (already built) | B14: 15000 | C14: 0 | D14: =B14-C14 -> 15000 | E14: Existing post-and-rail or wire
A15: First septic system | B15: 10000 | C15: 0 | D15: =B15-C15 -> 10000 | E15: Farmhouse septic already exists
A16: Barn/outbuilding (repurpose as temp hall) | B16: 0 | C16: 0 | D16: =B16-C16 -> 0 | E16: Existing barn = Phase 1 gathering space
A17: Established soil/pasture/orchards | B17: 0 | C17: 0 | D17: =B17-C17 -> 0 | E17: Years of soil building — priceless
A18: Total Infrastructure Savings | B18: =SUM(B11:B17) -> 85000 | C18: =SUM(C11:C17) -> 0 | E18: What you DON'T have to build
A20: CLT Formation & Closing | B20: 12000 | C20: 12000 | D20: =B20-C20 -> 0 | E20: Same either way
A22: PHASE 1 TOTAL | B22: =B8+B18+B20 -> 297000 | C22: =C8+C18+C20 -> 287000 | E22: Land + infrastructure + legal
A23: Phase 1 Savings vs Raw Land | C23: =B22-C22 -> 10000 | D23: =B22-C22 -> 10000 | E23: Positive = improved land is cheaper overall
A25: PHASE 2: Community Hall & Farm Infra
A26: Community hall (new build vs barn retrofit) | B26: 200000 | C26: 80000 | D26: =B26-C26 -> 120000 | E26: Retrofitting existing barn saves $100K+
A27: Farm infrastructure (irrigation, add'l fencing) | B27: 50000 | C27: 20000 | D27: =B27-C27 -> 30000 | E27: Much already exists
A28: Phase 2 Total | B28: =B26+B27 -> 250000 | C28: =C26+C27 -> 100000
A30: TOTAL PROJECT COST (All Phases) | B30: =B22+B28 -> 547000 | C30: =C22+C28 -> 387000
A31: Total Savings from Improved Farmland | C31: =B30-C30 -> 160000 | D31: =B30-C30 -> 160000 | E31: Positive = net savings
A32: Savings as % of Raw Land Cost | C32: =IF(B30=0,0,D31/B30) -> 0.29250457 | D32: =IF(B30=0,0,D31/B30) -> 0.29250457
A34: ACQUISITION STRUCTURES FOR RETIRING FARMERS
A36: Structure | B36: How It Works | C36: Cost to CLT | D36: Benefit to Farmer | E36: Best When
A37: Straight Sale at Market Value | B37: CLT purchases at full appraised value | C37: =C8 -> 275000 | D37: Full cash at closing | E37: Farmer needs max proceeds; CLT has strong capital stack
A38: Bargain Sale (below market) | B38: Farmer sells 20-40% below market; difference is tax-deductible donation to 501(c)(3) | C38: =C8*0.7 -> 192500 | D38: Cash + charitable deduction worth 30% of market value | E38: Farmer has tax liability to offset; cares about legacy
A39: Donation (full gift) | B39: Farmer donates land to CLT; takes full charitable deduction | C39: 0 | D39: Charitable deduction of full appraised value (up to 30% of AGI, 15-yr carryforward) | E39: High-net-worth farmer; strong legacy motivation; estate planning
A40: Life Estate | B40: CLT buys land but farmer retains right to live on a portion until death | C40: =C8*0.65 -> 178750 | D40: Below-market cash + lifetime housing security | E40: Farmer wants to age in place; CLT gets discount for delayed full access
A41: Installment Sale | B41: Farmer sells to CLT with seller financing over 5-15 years | C41: =C8 -> 275000 | D41: Steady income stream; spreads tax liability across years | E41: Farmer wants retirement income; CLT needs time to build capital
A42: Lease-to-Own | B42: CLT leases land for 3-5 years with purchase option; lease payments credited toward price | C42: Annual lease: $15K-$25K | D42: Immediate income; time to consider | E42: Both parties want a trial period; CLT is still raising capital
A44: FARMER LEGACY PIPELINE — KEY NETWORK CONTACTS
A46: Organization Type | B46: What They Do | C46: Why They Matter | D46: How to Connect
A47: USDA Cooperative Extension | B47: County-level farm education and support | C47: Know every aging farmer in their district; already having succession conversations | D47: Visit local extension office; attend farm field days
A48: State Farmland Preservation Program | B48: Buy conservation easements; preserve ag land | C48: Have database of farms with easements; know which farmers are approaching retirement | D48: Contact state dept of agriculture; attend board meetings
A49: Farm Link Programs (~30 states) | B49: Connect retiring farmers with beginning farmers | C49: Their entire mission is succession; they'll understand your model immediately | D49: farmlink.net directory; state beginning farmer coalitions
A50: American Farmland Trust (AFT) | B50: National farmland conservation; No Farms No Food campaign | C50: Research, policy advocacy, Farmland Finder tool; credibility by association | D50: farmland.org; regional offices; annual summit
...

Sheet P&L — Conservative
A1: SOVEREIGN MISFIT FARM — CONSERVATIVE SCENARIO
A2: 10-Year Profit & Loss Projection
B4: 2026 | C4: 2027 | D4: 2028 | E4: 2029 | F4: 2030 | G4: 2031 | H4: 2032 | I4: 2033 | J4: 2034 | K4: 2035 | L4: 10-Yr Total
A5: REVENUE
A6: Ground Lease Revenue | B6: =Assumptions!B20*Assumptions!B18*(1+Assumptions!B19)^0*12 -> 21600 | C6: =Assumptions!B21*Assumptions!B18*(1+Assumptions!B19)^1*12 -> 38556 | D6: =Assumptions!B22*Assumptions!B18*(1+Assumptions!B19)^2*12 -> 50563.44 | E6: =Assumptions!B23*(1-Assumptions!B24)*Assumptions!B18*(1+Assumptions!B19)^3*12 -> 59883.967 | F6: =Assumptions!B23*(1-Assumptions!B24)*Assumptions!B18*(1+Assumptions!B19)^4*12 -> 61081.647 | G6: =Assumptions!B23*(1-Assumptions!B24)*Assumptions!B18*(1+Assumptions!B19)^5*12 -> 62303.28 | H6: =Assumptions!B23*(1-Assumptions!B24)*Assumptions!B18*(1+Assumptions!B19)^6*12 -> 63549.345 | I6: =Assumptions!B23*(1-Assumptions!B24)*Assumptions!B18*(1+Assumptions!B19)^7*12 -> 64820.332 | J6: =Assumptions!B23*(1-Assumptions!B24)*Assumptions!B18*(1+Assumptions!B19)^8*12 -> 66116.739 | K6: =Assumptions!B23*(1-Assumptions!B24)*Assumptions!B18*(1+Assumptions!B19)^9*12 -> 67439.074 | L6: =SUM(B6:K6) -> 555913.82
A7: CSA Subscriptions | B7: =(Assumptions!B27)*(Assumptions!B29*(1+Assumptions!B30)^0) -> 12000 | C7: =(Assumptions!B27+(Assumptions!B28-Assumptions!B27)*1/4)*(Assumptions!B29*(1+Assumptions!B30)^1) -> 16995 | D7: =(Assumptions!B27+(Assumptions!B28-Assumptions!B27)*2/4)*(Assumptions!B29*(1+Assumptions!B30)^2) -> 22278.9 | E7: =(Assumptions!B27+(Assumptions!B28-Assumptions!B27)*3/4)*(Assumptions!B29*(1+Assumptions!B30)^3) -> 27864.538 | F7: =(Assumptions!B28)*(Assumptions!B29*(1+Assumptions!B30)^4) -> 33765.264 | G7: =(Assumptions!B28)*(Assumptions!B29*(1+Assumptions!B30)^5) -> 34778.222 | H7: =(Assumptions!B28)*(Assumptions!B29*(1+Assumptions!B30)^6) -> 35821.569 | I7: =(Assumptions!B28)*(Assumptions!B29*(1+Assumptions!B30)^7) -> 36896.216 | J7: =(Assumptions!B28)*(Assumptions!B29*(1+Assumptions!B30)^8) -> 38003.102 | K7: =(Assumptions!B28)*(Assumptions!B29*(1+Assumptions!B30)^9) -> 39143.196 | L7: =SUM(B7:K7) -> 297546.01
A8: Farm Stand Sales | B8: =Assumptions!B31*(1+Assumptions!B32)^0*Assumptions!B33 -> 8000 | C8: =Assumptions!B31*(1+Assumptions!B32)^1*Assumptions!B33 -> 8400 | D8: =Assumptions!B31*(1+Assumptions!B32)^2*Assumptions!B33 -> 8820 | E8: =Assumptions!B31*(1+Assumptions!B32)^3*Assumptions!B33 -> 9261 | F8: =Assumptions!B31*(1+Assumptions!B32)^4*Assumptions!B33 -> 9724.05 | G8: =Assumptions!B31*(1+Assumptions!B32)^5*Assumptions!B33 -> 10210.253 | H8: =Assumptions!B31*(1+Assumptions!B32)^6*Assumptions!B33 -> 10720.765 | I8: =Assumptions!B31*(1+Assumptions!B32)^7*Assumptions!B33 -> 11256.803 | J8: =Assumptions!B31*(1+Assumptions!B32)^8*Assumptions!B33 -> 11819.644 | K8: =Assumptions!B31*(1+Assumptions!B32)^9*Assumptions!B33 -> 12410.626 | L8: =SUM(B8:K8) -> 100623.14
A9: Value-Added Products | B9: =Assumptions!B34*(1+Assumptions!B35)^0 -> 3000 | C9: =Assumptions!B34*(1+Assumptions!B35)^1 -> 3300 | D9: =Assumptions!B34*(1+Assumptions!B35)^2 -> 3630 | E9: =Assumptions!B34*(1+Assumptions!B35)^3 -> 3993 | F9: =Assumptions!B34*(1+Assumptions!B35)^4 -> 4392.3 | G9: =Assumptions!B34*(1+Assumptions!B35)^5 -> 4831.53 | H9: =Assumptions!B34*(1+Assumptions!B35)^6 -> 5314.683 | I9: =Assumptions!B34*(1+Assumptions!B35)^7 -> 5846.1513 | J9: =Assumptions!B34*(1+Assumptions!B35)^8 -> 6430.7664 | K9: =Assumptions!B34*(1+Assumptions!B35)^9 -> 7073.8431 | L9: =SUM(B9:K9) -> 47812.274
A10: Workshops & Classes | B10: =(Assumptions!B38)*Assumptions!B40*(Assumptions!B41*(1+Assumptions!B42)^0) -> 3000 | C10: =(Assumptions!B38+(Assumptions!B39-Assumptions!B38)*1/3)*Assumptions!B40*(Assumptions!B41*(1+Assumptions!B42)^1) -> 5100 | D10: =(Assumptions!B38+(Assumptions!B39-Assumptions!B38)*2/3)*Assumptions!B40*(Assumptions!B41*(1+Assumptions!B42)^2) -> 7282.8 | E10: =(Assumptions!B39)*Assumptions!B40*(Assumptions!B41*(1+Assumptions!B42)^3) -> 9550.872 | F10: =(Assumptions!B39)*Assumptions!B40*(Assumptions!B41*(1+Assumptions!B42)^4) -> 9741.8894 | G10: =(Assumptions!B39)*Assumptions!B40*(Assumptions!B41*(1+Assumptions!B42)^5) -> 9936.7272 | H10: =(Assumptions!B39)*Assumptions!B40*(Assumptions!B41*(1+Assumptions!B42)^6) -> 10135.462 | I10: =(Assumptions!B39)*Assumptions!B40*(Assumptions!B41*(1+Assumptions!B42)^7) -> 10338.171 | J10: =(Assumptions!B39)*Assumptions!B40*(Assumptions!B41*(1+Assumptions!B42)^8) -> 10544.934 | K10: =(Assumptions!B39)*Assumptions!B40*(Assumptions!B41*(1+Assumptions!B42)^9) -> 10755.833 | L10: =SUM(B10:K10) -> 86386.689
A11: Farm Tours & Agritourism | B11: =Assumptions!B43*(1+Assumptions!B44)^0 -> 1000 | C11: =Assumptions!B43*(1+Assumptions!B44)^1 -> 1100 | D11: =Assumptions!B43*(1+Assumptions!B44)^2 -> 1210 | E11: =Assumptions!B43*(1+Assumptions!B44)^3 -> 1331 | F11: =Assumptions!B43*(1+Assumptions!B44)^4 -> 1464.1 | G11: =Assumptions!B43*(1+Assumptions!B44)^5 -> 1610.51 | H11: =Assumptions!B43*(1+Assumptions!B44)^6 -> 1771.561 | I11: =Assumptions!B43*(1+Assumptions!B44)^7 -> 1948.7171 | J11: =Assumptions!B43*(1+Assumptions!B44)^8 -> 2143.5888 | K11: =Assumptions!B43*(1+Assumptions!B44)^9 -> 2357.9477 | L11: =SUM(B11:K11) -> 15937.425
A12: Community Kitchen Rental | B12: 0 | C12: =Assumptions!B45*Assumptions!B46*(1+Assumptions!B42)^1 -> 1632 | D12: =Assumptions!B45*Assumptions!B46*(1+Assumptions!B42)^2 -> 1664.64 | E12: =Assumptions!B45*Assumptions!B46*(1+Assumptions!B42)^3 -> 1697.9328 | F12: =Assumptions!B45*Assumptions!B46*(1+Assumptions!B42)^4 -> 1731.8915 | G12: =Assumptions!B45*Assumptions!B46*(1+Assumptions!B42)^5 -> 1766.5293 | H12: =Assumptions!B45*Assumptions!B46*(1+Assumptions!B42)^6 -> 1801.8599 | I12: =Assumptions!B45*Assumptions!B46*(1+Assumptions!B42)^7 -> 1837.8971 | J12: =Assumptions!B45*Assumptions!B46*(1+Assumptions!B42)^8 -> 1874.655 | K12: =Assumptions!B45*Assumptions!B46*(1+Assumptions!B42)^9 -> 1912.1481 | L12: =SUM(B12:K12) -> 15919.554
A14: TOTAL REVENUE | B14: =SUM(B6:B12) -> 48600 | C14: =SUM(C6:C12) -> 75083 | D14: =SUM(D6:D12) -> 95449.78 | E14: =SUM(E6:E12) -> 113582.31 | F14: =SUM(F6:F12) -> 121901.14 | G14: =SUM(G6:G12) -> 125437.05 | H14: =SUM(H6:H12) -> 129115.24 | I14: =SUM(I6:I12) -> 132944.29 | ... L14: =SUM(L6:L12) -> 1120138.9
A16: OPERATING EXPENSES
A17: Property Tax | B17: =Assumptions!B49*(1+Assumptions!B59)^0 -> 4000 | C17: =Assumptions!B49*(1+Assumptions!B59)^1 -> 4120 | D17: =Assumptions!B49*(1+Assumptions!B59)^2 -> 4243.6 | E17: =Assumptions!B49*(1+Assumptions!B59)^3 -> 4370.908 | F17: =Assumptions!B49*(1+Assumptions!B59)^4 -> 4502.0352 | G17: =Assumptions!B49*(1+Assumptions!B59)^5 -> 4637.0963 | H17: =Assumptions!B49*(1+Assumptions!B59)^6 -> 4776.2092 | I17: =Assumptions!B49*(1+Assumptions!B59)^7 -> 4919.4955 | J17: =Assumptions!B49*(1+Assumptions!B59)^8 -> 5067.0803 | K17: =Assumptions!B49*(1+Assumptions!B59)^9 -> 5219.0927 | L17: =SUM(B17:K17) -> 45855.517
A18: Property Insurance | B18: =Assumptions!B50*(1+Assumptions!B59)^0 -> 8000 | C18: =Assumptions!B50*(1+Assumptions!B59)^1 -> 8240 | D18: =Assumptions!B50*(1+Assumptions!B59)^2 -> 8487.2 | E18: =Assumptions!B50*(1+Assumptions!B59)^3 -> 8741.816 | F18: =Assumptions!B50*(1+Assumptions!B59)^4 -> 9004.0705 | G18: =Assumptions!B50*(1+Assumptions!B59)^5 -> 9274.1926 | H18: =Assumptions!B50*(1+Assumptions!B59)^6 -> 9552.4184 | I18: =Assumptions!B50*(1+Assumptions!B59)^7 -> 9838.9909 | J18: =Assumptions!B50*(1+Assumptions!B59)^8 -> 10134.161 | K18: =Assumptions!B50*(1+Assumptions!B59)^9 -> 10438.185 | L18: =SUM(B18:K18) -> 91711.034
A19: Utilities (Common Areas) | B19: =Assumptions!B51*(1+Assumptions!B59)^0 -> 6000 | C19: =Assumptions!B51*(1+Assumptions!B59)^1 -> 6180 | D19: =Assumptions!B51*(1+Assumptions!B59)^2 -> 6365.4 | E19: =Assumptions!B51*(1+Assumptions!B59)^3 -> 6556.362 | F19: =Assumptions!B51*(1+Assumptions!B59)^4 -> 6753.0529 | G19: =Assumptions!B51*(1+Assumptions!B59)^5 -> 6955.6444 | H19: =Assumptions!B51*(1+Assumptions!B59)^6 -> 7164.3138 | I19: =Assumptions!B51*(1+Assumptions!B59)^7 -> 7379.2432 | J19: =Assumptions!B51*(1+Assumptions!B59)^8 -> 7600.6205 | K19: =Assumptions!B51*(1+Assumptions!B59)^9 -> 7828.6391 | L19: =SUM(B19:K19) -> 68783.276
A20: Farm Operating Costs | B20: =Assumptions!B53*(1+Assumptions!B54)^0 -> 12000 | C20: =Assumptions!B53*(1+Assumptions!B54)^1 -> 12600 | D20: =Assumptions!B53*(1+Assumptions!B54)^2 -> 13230 | E20: =Assumptions!B53*(1+Assumptions!B54)^3 -> 13891.5 | F20: =Assumptions!B53*(1+Assumptions!B54)^4 -> 14586.075 | G20: =Assumptions!B53*(1+Assumptions!B54)^5 -> 15315.379 | H20: =Assumptions!B53*(1+Assumptions!B54)^6 -> 16081.148 | I20: =Assumptions!B53*(1+Assumptions!B54)^7 -> 16885.205 | J20: =Assumptions!B53*(1+Assumptions!B54)^8 -> 17729.465 | K20: =Assumptions!B53*(1+Assumptions!B54)^9 -> 18615.939 | L20: =SUM(B20:K20) -> 150934.71
A21: Admin / Legal / Accounting | B21: =Assumptions!B55*(1+Assumptions!B59)^0 -> 8000 | C21: =Assumptions!B55*(1+Assumptions!B59)^1 -> 8240 | D21: =Assumptions!B55*(1+Assumptions!B59)^2 -> 8487.2 | E21: =Assumptions!B55*(1+Assumptions!B59)^3 -> 8741.816 | F21: =Assumptions!B55*(1+Assumptions!B59)^4 -> 9004.0705 | G21: =Assumptions!B55*(1+Assumptions!B59)^5 -> 9274.1926 | H21: =Assumptions!B55*(1+Assumptions!B59)^6 -> 9552.4184 | I21: =Assumptions!B55*(1+Assumptions!B59)^7 -> 9838.9909 | J21: =Assumptions!B55*(1+Assumptions!B59)^8 -> 10134.161 | K21: =Assumptions!B55*(1+Assumptions!B59)^9 -> 10438.185 | L21: =SUM(B21:K21) -> 91711.034
A22: Marketing & Outreach | B22: =Assumptions!B56*(1+Assumptions!B59)^0 -> 2000 | C22: =Assumptions!B56*(1+Assumptions!B59)^1 -> 2060 | D22: =Assumptions!B56*(1+Assumptions!B59)^2 -> 2121.8 | E22: =Assumptions!B56*(1+Assumptions!B59)^3 -> 2185.454 | F22: =Assumptions!B56*(1+Assumptions!B59)^4 -> 2251.0176 | G22: =Assumptions!B56*(1+Assumptions!B59)^5 -> 2318.5481 | H22: =Assumptions!B56*(1+Assumptions!B59)^6 -> 2388.1046 | I22: =Assumptions!B56*(1+Assumptions!B59)^7 -> 2459.7477 | J22: =Assumptions!B56*(1+Assumptions!B59)^8 -> 2533.5402 | K22: =Assumptions!B56*(1+Assumptions!B59)^9 -> 2609.5464 | L22: =SUM(B22:K22) -> 22927.759
A23: Community Coordinator | B23: =Assumptions!B57*(1+Assumptions!B59)^0 -> 0 | C23: =Assumptions!B57*(1+Assumptions!B59)^1 -> 0 | D23: =Assumptions!B58*(1+Assumptions!B59)^2 -> 15913.5 | E23: =Assumptions!B58*(1+Assumptions!B59)^3 -> 16390.905 | F23: =Assumptions!B58*(1+Assumptions!B59)^4 -> 16882.632 | G23: =Assumptions!B58*(1+Assumptions!B59)^5 -> 17389.111 | H23: =Assumptions!B58*(1+Assumptions!B59)^6 -> 17910.784 | I23: =Assumptions!B58*(1+Assumptions!B59)^7 -> 18448.108 | J23: =Assumptions!B58*(1+Assumptions!B59)^8 -> 19001.551 | K23: =Assumptions!B58*(1+Assumptions!B59)^9 -> 19571.598 | L23: =SUM(B23:K23) -> 141508.19
A24: Maintenance Reserve | B24: =B14*Assumptions!B52 -> 3888 | C24: =C14*Assumptions!B52 -> 6006.64 | D24: =D14*Assumptions!B52 -> 7635.9824 | E24: =E14*Assumptions!B52 -> 9086.5849 | F24: =F14*Assumptions!B52 -> 9752.0914 | G24: =G14*Assumptions!B52 -> 10034.964 | H24: =H14*Assumptions!B52 -> 10329.22 | I24: =I14*Assumptions!B52 -> 10635.543 | J24: =J14*Assumptions!B52 -> 10954.674 | K24: =K14*Assumptions!B52 -> 11287.413 | L24: =SUM(B24:K24) -> 89611.113
A26: TOTAL OPERATING EXPENSES | B26: =SUM(B17:B24) -> 43888 | C26: =SUM(C17:C24) -> 47446.64 | D26: =SUM(D17:D24) -> 66484.682 | E26: =SUM(E17:E24) -> 69965.346 | F26: =SUM(F17:F24) -> 72735.045 | G26: =SUM(G17:G24) -> 75199.128 | H26: =SUM(H17:H24) -> 77754.616 | I26: =SUM(I17:I24) -> 80405.324 | ... L26: =SUM(L17:L24) -> 703042.63
A28: OPERATING INCOME (EBITDA) | B28: =B14-B26 -> 4712 | C28: =C14-C26 -> 27636.36 | D28: =D14-D26 -> 28965.098 | E28: =E14-E26 -> 43616.965 | F28: =F14-F26 -> 49166.097 | G28: =G14-G26 -> 50237.923 | H28: =H14-H26 -> 51360.629 | I28: =I14-I26 -> 52538.964 | ... L28: =L14-L26 -> 417096.28
A29: Operating Margin | B29: =IF(B14=0,0,B28/B14) -> 0.096954733 | C29: =IF(C14=0,0,C28/C14) -> 0.36807746 | D29: =IF(D14=0,0,D28/D14) -> 0.30345903 | E29: =IF(E14=0,0,E28/E14) -> 0.38401195 | F29: =IF(F14=0,0,F28/F14) -> 0.40332761 | G29: =IF(G14=0,0,G28/G14) -> 0.40050306 | H29: =IF(H14=0,0,H28/H14) -> 0.39778904 | I29: =IF(I14=0,0,I28/I14) -> 0.39519534 | ... L29: =IF(L14=0,0,L28/L14) -> 0.37236121
A31: DEBT SERVICE
A32: Annual Loan Payment | B32: =Assumptions!B98 -> 22919.833 | C32: =Assumptions!B98 -> 22919.833 | D32: =Assumptions!B98 -> 22919.833 | E32: =Assumptions!B98 -> 22919.833 | F32: =Assumptions!B98 -> 22919.833 | G32: =Assumptions!B98 -> 22919.833 | H32: =Assumptions!B98 -> 22919.833 | I32: =Assumptions!B98 -> 22919.833 | J32: =Assumptions!B98 -> 22919.833 | K32: =Assumptions!B98 -> 22919.833 | L32: =SUM(B32:K32) -> 229198.33
A34: NET INCOME (after debt service) | B34: =B28-B32 -> -18207.833 | C34: =C28-C32 -> 4716.5275 | D34: =D28-D32 -> 6045.2651 | E34: =E28-E32 -> 20697.132 | F34: =F28-F32 -> 26246.264 | G34: =G28-G32 -> 27318.09 | H34: =H28-H32 -> 28440.796 | I34: =I28-I32 -> 29619.131 | ... L34: =L28-L32 -> 187897.95
A35: Net Margin | B35: =IF(B14=0,0,B34/B14) -> -0.37464676 | C35: =IF(C14=0,0,C34/C14) -> 0.062817515 | D35: =IF(D14=0,0,D34/D14) -> 0.06333451 | E35: =IF(E14=0,0,E34/E14) -> 0.18222144 | F35: =IF(F14=0,0,F34/F14) -> 0.21530778 | G35: =IF(G14=0,0,G34/G14) -> 0.21778326 | H35: =IF(H14=0,0,H34/H14) -> 0.2202745 | I35: =IF(I14=0,0,I34/I14) -> 0.22279356 | ... L35: =IF(L14=0,0,L34/L14) -> 0.16774523
A37: CASH FLOW & RESERVES
A38: Beginning Cash Balance | B38: =Assumptions!B92 -> 20000 | C38: =B40 -> 1792.1675 | D38: =C40 -> 6508.695 | E38: =D40 -> 12553.96 | F38: =E40 -> 33251.092 | G38: =F40 -> 59497.357 | H38: =G40 -> 86815.447 | I38: =H40 -> 115256.24 | J38: =I40 -> 144875.37 | K38: =J40 -> 175733.72
A39: Net Cash Flow (this year) | B39: =B34 -> -18207.833 | C39: =C34 -> 4716.5275 | D39: =D34 -> 6045.2651 | E39: =E34 -> 20697.132 | F39: =F34 -> 26246.264 | G39: =G34 -> 27318.09 | H39: =H34 -> 28440.796 | I39: =I34 -> 29619.131 | ... K39: =K34 -> 32164.236
A40: Ending Cash Balance | B40: =B38+B39 -> 1792.1675 | C40: =C38+C39 -> 6508.695 | D40: =D38+D39 -> 12553.96 | E40: =E38+E39 -> 33251.092 | F40: =F38+F39 -> 59497.357 | G40: =G38+G39 -> 86815.447 | H40: =H38+H39 -> 115256.24 | I40: =I38+I39 -> 144875.37 | ... K40: =K38+K39 -> 207897.95
A42: Debt Service Coverage Ratio | B42: =IF(B32=0,0,B28/B32) -> 0.20558614 | C42: =IF(C32=0,0,C28/C32) -> 1.2057837 | D42: =IF(D32=0,0,D28/D32) -> 1.2637569 | E42: =IF(E32=0,0,E28/E32) -> 1.9030228 | F42: =IF(F32=0,0,F28/F32) -> 2.1451333 | G42: =IF(G32=0,0,G28/G32) -> 2.1918975 | H42: =IF(H32=0,0,H28/H32) -> 2.2408815 | I42: =IF(I32=0,0,I28/I32) -> 2.2922927 | ... K42: =IF(K32=0,0,K28/K32) -> 2.4033364
A43: Target: >1.25x for lender comfort
A45: REVENUE MIX (Year 5)
A46: Ground Lease % | B46: =IF(F14=0,0,F6/F14) -> 0.50107526
A47: CSA % | B47: =IF(F14=0,0,F7/F14) -> 0.27698891
A48: Farm Stand % | B48: =IF(F14=0,0,F8/F14) -> 0.079769966
A49: Value-Added % | B49: =IF(F14=0,0,F9/F14) -> 0.036031656
A50: Workshops % | B50: =IF(F14=0,0,F10/F14) -> 0.07991631
...

Sheet P&L — Moderate
A1: SOVEREIGN MISFIT FARM — MODERATE SCENARIO
A2: 10-Year Profit & Loss Projection
B4: 2026 | C4: 2027 | D4: 2028 | E4: 2029 | F4: 2030 | G4: 2031 | H4: 2032 | I4: 2033 | J4: 2034 | K4: 2035 | L4: 10-Yr Total
A5: REVENUE
A6: Ground Lease Revenue | B6: =Assumptions!C20*Assumptions!C18*(1+Assumptions!C19)^0*12 -> 30000 | C6: =Assumptions!C21*Assumptions!C18*(1+Assumptions!C19)^1*12 -> 49200 | D6: =Assumptions!C22*Assumptions!C18*(1+Assumptions!C19)^2*12 -> 63037.5 | E6: =Assumptions!C23*(1-Assumptions!C24)*Assumptions!C18*(1+Assumptions!C19)^3*12 -> 75210.041 | F6: =Assumptions!C23*(1-Assumptions!C24)*Assumptions!C18*(1+Assumptions!C19)^4*12 -> 77090.292 | G6: =Assumptions!C23*(1-Assumptions!C24)*Assumptions!C18*(1+Assumptions!C19)^5*12 -> 79017.55 | H6: =Assumptions!C23*(1-Assumptions!C24)*Assumptions!C18*(1+Assumptions!C19)^6*12 -> 80992.988 | I6: =Assumptions!C23*(1-Assumptions!C24)*Assumptions!C18*(1+Assumptions!C19)^7*12 -> 83017.813 | J6: =Assumptions!C23*(1-Assumptions!C24)*Assumptions!C18*(1+Assumptions!C19)^8*12 -> 85093.258 | K6: =Assumptions!C23*(1-Assumptions!C24)*Assumptions!C18*(1+Assumptions!C19)^9*12 -> 87220.59 | L6: =SUM(B6:K6) -> 709880.03
A7: CSA Subscriptions | B7: =(Assumptions!C27)*(Assumptions!C29*(1+Assumptions!C30)^0) -> 19500 | C7: =(Assumptions!C27+(Assumptions!C28-Assumptions!C27)*1/4)*(Assumptions!C29*(1+Assumptions!C30)^1) -> 27616.875 | D7: =(Assumptions!C27+(Assumptions!C28-Assumptions!C27)*2/4)*(Assumptions!C29*(1+Assumptions!C30)^2) -> 36203.213 | E7: =(Assumptions!C27+(Assumptions!C28-Assumptions!C27)*3/4)*(Assumptions!C29*(1+Assumptions!C30)^3) -> 45279.875 | F7: =(Assumptions!C28)*(Assumptions!C29*(1+Assumptions!C30)^4) -> 54868.554 | G7: =(Assumptions!C28)*(Assumptions!C29*(1+Assumptions!C30)^5) -> 56514.611 | H7: =(Assumptions!C28)*(Assumptions!C29*(1+Assumptions!C30)^6) -> 58210.049 | I7: =(Assumptions!C28)*(Assumptions!C29*(1+Assumptions!C30)^7) -> 59956.351 | J7: =(Assumptions!C28)*(Assumptions!C29*(1+Assumptions!C30)^8) -> 61755.041 | K7: =(Assumptions!C28)*(Assumptions!C29*(1+Assumptions!C30)^9) -> 63607.693 | L7: =SUM(B7:K7) -> 483512.26
A8: Farm Stand Sales | B8: =Assumptions!C31*(1+Assumptions!C32)^0*Assumptions!C33 -> 14400 | C8: =Assumptions!C31*(1+Assumptions!C32)^1*Assumptions!C33 -> 15552 | D8: =Assumptions!C31*(1+Assumptions!C32)^2*Assumptions!C33 -> 16796.16 | E8: =Assumptions!C31*(1+Assumptions!C32)^3*Assumptions!C33 -> 18139.853 | F8: =Assumptions!C31*(1+Assumptions!C32)^4*Assumptions!C33 -> 19591.041 | G8: =Assumptions!C31*(1+Assumptions!C32)^5*Assumptions!C33 -> 21158.324 | H8: =Assumptions!C31*(1+Assumptions!C32)^6*Assumptions!C33 -> 22850.99 | I8: =Assumptions!C31*(1+Assumptions!C32)^7*Assumptions!C33 -> 24679.069 | J8: =Assumptions!C31*(1+Assumptions!C32)^8*Assumptions!C33 -> 26653.395 | K8: =Assumptions!C31*(1+Assumptions!C32)^9*Assumptions!C33 -> 28785.667 | L8: =SUM(B8:K8) -> 208606.5
A9: Value-Added Products | B9: =Assumptions!C34*(1+Assumptions!C35)^0 -> 5000 | C9: =Assumptions!C34*(1+Assumptions!C35)^1 -> 5750 | D9: =Assumptions!C34*(1+Assumptions!C35)^2 -> 6612.5 | E9: =Assumptions!C34*(1+Assumptions!C35)^3 -> 7604.375 | F9: =Assumptions!C34*(1+Assumptions!C35)^4 -> 8745.0312 | G9: =Assumptions!C34*(1+Assumptions!C35)^5 -> 10056.786 | H9: =Assumptions!C34*(1+Assumptions!C35)^6 -> 11565.304 | I9: =Assumptions!C34*(1+Assumptions!C35)^7 -> 13300.099 | J9: =Assumptions!C34*(1+Assumptions!C35)^8 -> 15295.114 | K9: =Assumptions!C34*(1+Assumptions!C35)^9 -> 17589.381 | L9: =SUM(B9:K9) -> 101518.59
A10: Workshops & Classes | B10: =(Assumptions!C38)*Assumptions!C40*(Assumptions!C41*(1+Assumptions!C42)^0) -> 7800 | C10: =(Assumptions!C38+(Assumptions!C39-Assumptions!C38)*1/3)*Assumptions!C40*(Assumptions!C41*(1+Assumptions!C42)^1) -> 11783.2 | D10: =(Assumptions!C38+(Assumptions!C39-Assumptions!C38)*2/3)*Assumptions!C40*(Assumptions!C41*(1+Assumptions!C42)^2) -> 15998.372 | E10: =(Assumptions!C39)*Assumptions!C40*(Assumptions!C41*(1+Assumptions!C42)^3) -> 20455.849 | F10: =(Assumptions!C39)*Assumptions!C40*(Assumptions!C41*(1+Assumptions!C42)^4) -> 21069.525 | G10: =(Assumptions!C39)*Assumptions!C40*(Assumptions!C41*(1+Assumptions!C42)^5) -> 21701.611 | H10: =(Assumptions!C39)*Assumptions!C40*(Assumptions!C41*(1+Assumptions!C42)^6) -> 22352.659 | I10: =(Assumptions!C39)*Assumptions!C40*(Assumptions!C41*(1+Assumptions!C42)^7) -> 23023.239 | J10: =(Assumptions!C39)*Assumptions!C40*(Assumptions!C41*(1+Assumptions!C42)^8) -> 23713.936 | K10: =(Assumptions!C39)*Assumptions!C40*(Assumptions!C41*(1+Assumptions!C42)^9) -> 24425.354 | L10: =SUM(B10:K10) -> 192323.74
A11: Farm Tours & Agritourism | B11: =Assumptions!C43*(1+Assumptions!C44)^0 -> 2000 | C11: =Assumptions!C43*(1+Assumptions!C44)^1 -> 2300 | D11: =Assumptions!C43*(1+Assumptions!C44)^2 -> 2645 | E11: =Assumptions!C43*(1+Assumptions!C44)^3 -> 3041.75 | F11: =Assumptions!C43*(1+Assumptions!C44)^4 -> 3498.0125 | G11: =Assumptions!C43*(1+Assumptions!C44)^5 -> 4022.7144 | H11: =Assumptions!C43*(1+Assumptions!C44)^6 -> 4626.1215 | I11: =Assumptions!C43*(1+Assumptions!C44)^7 -> 5320.0398 | J11: =Assumptions!C43*(1+Assumptions!C44)^8 -> 6118.0457 | K11: =Assumptions!C43*(1+Assumptions!C44)^9 -> 7035.7526 | L11: =SUM(B11:K11) -> 40607.436
A12: Community Kitchen Rental | B12: 0 | C12: =Assumptions!C45*Assumptions!C46*(1+Assumptions!C42)^1 -> 3605 | D12: =Assumptions!C45*Assumptions!C46*(1+Assumptions!C42)^2 -> 3713.15 | E12: =Assumptions!C45*Assumptions!C46*(1+Assumptions!C42)^3 -> 3824.5445 | F12: =Assumptions!C45*Assumptions!C46*(1+Assumptions!C42)^4 -> 3939.2808 | G12: =Assumptions!C45*Assumptions!C46*(1+Assumptions!C42)^5 -> 4057.4593 | H12: =Assumptions!C45*Assumptions!C46*(1+Assumptions!C42)^6 -> 4179.183 | I12: =Assumptions!C45*Assumptions!C46*(1+Assumptions!C42)^7 -> 4304.5585 | J12: =Assumptions!C45*Assumptions!C46*(1+Assumptions!C42)^8 -> 4433.6953 | K12: =Assumptions!C45*Assumptions!C46*(1+Assumptions!C42)^9 -> 4566.7061 | L12: =SUM(B12:K12) -> 36623.578
A14: TOTAL REVENUE | B14: =SUM(B6:B12) -> 78700 | C14: =SUM(C6:C12) -> 115807.07 | D14: =SUM(D6:D12) -> 145005.89 | E14: =SUM(E6:E12) -> 173556.29 | F14: =SUM(F6:F12) -> 188801.74 | G14: =SUM(G6:G12) -> 196529.06 | H14: =SUM(H6:H12) -> 204777.3 | I14: =SUM(I6:I12) -> 213601.17 | ... L14: =SUM(L6:L12) -> 1773072.1
A16: OPERATING EXPENSES
A17: Property Tax | B17: =Assumptions!C49*(1+Assumptions!C59)^0 -> 2500 | C17: =Assumptions!C49*(1+Assumptions!C59)^1 -> 2575 | D17: =Assumptions!C49*(1+Assumptions!C59)^2 -> 2652.25 | E17: =Assumptions!C49*(1+Assumptions!C59)^3 -> 2731.8175 | F17: =Assumptions!C49*(1+Assumptions!C59)^4 -> 2813.772 | G17: =Assumptions!C49*(1+Assumptions!C59)^5 -> 2898.1852 | H17: =Assumptions!C49*(1+Assumptions!C59)^6 -> 2985.1307 | I17: =Assumptions!C49*(1+Assumptions!C59)^7 -> 3074.6847 | J17: =Assumptions!C49*(1+Assumptions!C59)^8 -> 3166.9252 | K17: =Assumptions!C49*(1+Assumptions!C59)^9 -> 3261.933 | L17: =SUM(B17:K17) -> 28659.698
A18: Property Insurance | B18: =Assumptions!C50*(1+Assumptions!C59)^0 -> 7000 | C18: =Assumptions!C50*(1+Assumptions!C59)^1 -> 7210 | D18: =Assumptions!C50*(1+Assumptions!C59)^2 -> 7426.3 | E18: =Assumptions!C50*(1+Assumptions!C59)^3 -> 7649.089 | F18: =Assumptions!C50*(1+Assumptions!C59)^4 -> 7878.5617 | G18: =Assumptions!C50*(1+Assumptions!C59)^5 -> 8114.9185 | H18: =Assumptions!C50*(1+Assumptions!C59)^6 -> 8358.3661 | I18: =Assumptions!C50*(1+Assumptions!C59)^7 -> 8609.1171 | J18: =Assumptions!C50*(1+Assumptions!C59)^8 -> 8867.3906 | K18: =Assumptions!C50*(1+Assumptions!C59)^9 -> 9133.4123 | L18: =SUM(B18:K18) -> 80247.155
A19: Utilities (Common Areas) | B19: =Assumptions!C51*(1+Assumptions!C59)^0 -> 5000 | C19: =Assumptions!C51*(1+Assumptions!C59)^1 -> 5150 | D19: =Assumptions!C51*(1+Assumptions!C59)^2 -> 5304.5 | E19: =Assumptions!C51*(1+Assumptions!C59)^3 -> 5463.635 | F19: =Assumptions!C51*(1+Assumptions!C59)^4 -> 5627.5441 | G19: =Assumptions!C51*(1+Assumptions!C59)^5 -> 5796.3704 | H19: =Assumptions!C51*(1+Assumptions!C59)^6 -> 5970.2615 | I19: =Assumptions!C51*(1+Assumptions!C59)^7 -> 6149.3693 | J19: =Assumptions!C51*(1+Assumptions!C59)^8 -> 6333.8504 | K19: =Assumptions!C51*(1+Assumptions!C59)^9 -> 6523.8659 | L19: =SUM(B19:K19) -> 57319.397
A20: Farm Operating Costs | B20: =Assumptions!C53*(1+Assumptions!C54)^0 -> 15000 | C20: =Assumptions!C53*(1+Assumptions!C54)^1 -> 15900 | D20: =Assumptions!C53*(1+Assumptions!C54)^2 -> 16854 | E20: =Assumptions!C53*(1+Assumptions!C54)^3 -> 17865.24 | F20: =Assumptions!C53*(1+Assumptions!C54)^4 -> 18937.154 | G20: =Assumptions!C53*(1+Assumptions!C54)^5 -> 20073.384 | H20: =Assumptions!C53*(1+Assumptions!C54)^6 -> 21277.787 | I20: =Assumptions!C53*(1+Assumptions!C54)^7 -> 22554.454 | J20: =Assumptions!C53*(1+Assumptions!C54)^8 -> 23907.721 | K20: =Assumptions!C53*(1+Assumptions!C54)^9 -> 25342.184 | L20: =SUM(B20:K20) -> 197711.92
A21: Admin / Legal / Accounting | B21: =Assumptions!C55*(1+Assumptions!C59)^0 -> 6000 | C21: =Assumptions!C55*(1+Assumptions!C59)^1 -> 6180 | D21: =Assumptions!C55*(1+Assumptions!C59)^2 -> 6365.4 | E21: =Assumptions!C55*(1+Assumptions!C59)^3 -> 6556.362 | F21: =Assumptions!C55*(1+Assumptions!C59)^4 -> 6753.0529 | G21: =Assumptions!C55*(1+Assumptions!C59)^5 -> 6955.6444 | H21: =Assumptions!C55*(1+Assumptions!C59)^6 -> 7164.3138 | I21: =Assumptions!C55*(1+Assumptions!C59)^7 -> 7379.2432 | J21: =Assumptions!C55*(1+Assumptions!C59)^8 -> 7600.6205 | K21: =Assumptions!C55*(1+Assumptions!C59)^9 -> 7828.6391 | L21: =SUM(B21:K21) -> 68783.276
A22: Marketing & Outreach | B22: =Assumptions!C56*(1+Assumptions!C59)^0 -> 3000 | C22: =Assumptions!C56*(1+Assumptions!C59)^1 -> 3090 | D22: =Assumptions!C56*(1+Assumptions!C59)^2 -> 3182.7 | E22: =Assumptions!C56*(1+Assumptions!C59)^3 -> 3278.181 | F22: =Assumptions!C56*(1+Assumptions!C59)^4 -> 3376.5264 | G22: =Assumptions!C56*(1+Assumptions!C59)^5 -> 3477.8222 | H22: =Assumptions!C56*(1+Assumptions!C59)^6 -> 3582.1569 | I22: =Assumptions!C56*(1+Assumptions!C59)^7 -> 3689.6216 | J22: =Assumptions!C56*(1+Assumptions!C59)^8 -> 3800.3102 | K22: =Assumptions!C56*(1+Assumptions!C59)^9 -> 3914.3196 | L22: =SUM(B22:K22) -> 34391.638
A23: Community Coordinator | B23: =Assumptions!C57*(1+Assumptions!C59)^0 -> 12000 | C23: =Assumptions!C57*(1+Assumptions!C59)^1 -> 12360 | D23: =Assumptions!C58*(1+Assumptions!C59)^2 -> 25461.6 | E23: =Assumptions!C58*(1+Assumptions!C59)^3 -> 26225.448 | F23: =Assumptions!C58*(1+Assumptions!C59)^4 -> 27012.211 | G23: =Assumptions!C58*(1+Assumptions!C59)^5 -> 27822.578 | H23: =Assumptions!C58*(1+Assumptions!C59)^6 -> 28657.255 | I23: =Assumptions!C58*(1+Assumptions!C59)^7 -> 29516.973 | J23: =Assumptions!C58*(1+Assumptions!C59)^8 -> 30402.482 | K23: =Assumptions!C58*(1+Assumptions!C59)^9 -> 31314.556 | L23: =SUM(B23:K23) -> 250773.1
A24: Maintenance Reserve | B24: =B14*Assumptions!C52 -> 4722 | C24: =C14*Assumptions!C52 -> 6948.4245 | D24: =D14*Assumptions!C52 -> 8700.3537 | E24: =E14*Assumptions!C52 -> 10413.377 | F24: =F14*Assumptions!C52 -> 11328.104 | G24: =G14*Assumptions!C52 -> 11791.743 | H24: =H14*Assumptions!C52 -> 12286.638 | I24: =I14*Assumptions!C52 -> 12816.07 | J24: =J14*Assumptions!C52 -> 13383.749 | K24: =K14*Assumptions!C52 -> 13993.869 | L24: =SUM(B24:K24) -> 106384.33
A26: TOTAL OPERATING EXPENSES | B26: =SUM(B17:B24) -> 55222 | C26: =SUM(C17:C24) -> 59413.425 | D26: =SUM(D17:D24) -> 75947.104 | E26: =SUM(E17:E24) -> 80183.15 | F26: =SUM(F17:F24) -> 83726.927 | G26: =SUM(G17:G24) -> 86930.646 | H26: =SUM(H17:H24) -> 90281.908 | I26: =SUM(I17:I24) -> 93789.533 | ... L26: =SUM(L17:L24) -> 824270.52
A28: OPERATING INCOME (EBITDA) | B28: =B14-B26 -> 23478 | C28: =C14-C26 -> 56393.651 | D28: =D14-D26 -> 69058.791 | E28: =E14-E26 -> 93373.138 | F28: =F14-F26 -> 105074.81 | G28: =G14-G26 -> 109598.41 | H28: =H14-H26 -> 114495.39 | I28: =I14-I26 -> 119811.64 | ... L28: =L14-L26 -> 948801.62
A29: Operating Margin | B29: =IF(B14=0,0,B28/B14) -> 0.29832274 | C29: =IF(C14=0,0,C28/C14) -> 0.48696205 | D29: =IF(D14=0,0,D28/D14) -> 0.47624816 | E29: =IF(E14=0,0,E28/E14) -> 0.53799917 | F29: =IF(F14=0,0,F28/F14) -> 0.55653519 | G29: =IF(G14=0,0,G28/G14) -> 0.55767026 | H29: =IF(H14=0,0,H28/H14) -> 0.55912149 | I29: =IF(I14=0,0,I28/I14) -> 0.56091283 | ... L29: =IF(L14=0,0,L28/L14) -> 0.53511733
A31: DEBT SERVICE
A32: Annual Loan Payment | B32: =Assumptions!C98 -> 16487.806 | C32: =Assumptions!C98 -> 16487.806 | D32: =Assumptions!C98 -> 16487.806 | E32: =Assumptions!C98 -> 16487.806 | F32: =Assumptions!C98 -> 16487.806 | G32: =Assumptions!C98 -> 16487.806 | H32: =Assumptions!C98 -> 16487.806 | I32: =Assumptions!C98 -> 16487.806 | J32: =Assumptions!C98 -> 16487.806 | K32: =Assumptions!C98 -> 16487.806 | L32: =SUM(B32:K32) -> 164878.06
A34: NET INCOME (after debt service) | B34: =B28-B32 -> 6990.1944 | C34: =C28-C32 -> 39905.845 | D34: =D28-D32 -> 52570.985 | E34: =E28-E32 -> 76885.333 | F34: =F28-F32 -> 88587.005 | G34: =G28-G32 -> 93110.604 | H34: =H28-H32 -> 98007.581 | I34: =I28-I32 -> 103323.83 | ... L34: =L28-L32 -> 783923.57
A35: Net Margin | B35: =IF(B14=0,0,B34/B14) -> 0.088820767 | C35: =IF(C14=0,0,C34/C14) -> 0.34458901 | D35: =IF(D14=0,0,D34/D14) -> 0.36254378 | E35: =IF(E14=0,0,E34/E14) -> 0.44299941 | F35: =IF(F14=0,0,F34/F14) -> 0.46920651 | G35: =IF(G14=0,0,G34/G14) -> 0.47377526 | H35: =IF(H14=0,0,H34/H14) -> 0.4786057 | I35: =IF(I14=0,0,I34/I14) -> 0.48372315 | ... L35: =IF(L14=0,0,L34/L14) -> 0.44212728
A37: CASH FLOW & RESERVES
A38: Beginning Cash Balance | B38: =Assumptions!C92 -> 230500 | C38: =B40 -> 237490.19 | D38: =C40 -> 277396.04 | E38: =D40 -> 329967.02 | F38: =E40 -> 406852.36 | G38: =F40 -> 495439.36 | H38: =G40 -> 588549.97 | I38: =H40 -> 686557.55 | J38: =I40 -> 789881.38 | K38: =J40 -> 898993.01
A39: Net Cash Flow (this year) | B39: =B34 -> 6990.1944 | C39: =C34 -> 39905.845 | D39: =D34 -> 52570.985 | E39: =E34 -> 76885.333 | F39: =F34 -> 88587.005 | G39: =G34 -> 93110.604 | H39: =H34 -> 98007.581 | I39: =I34 -> 103323.83 | ... K39: =K34 -> 115430.56
A40: Ending Cash Balance | B40: =B38+B39 -> 237490.19 | C40: =C38+C39 -> 277396.04 | D40: =D38+D39 -> 329967.02 | E40: =E38+E39 -> 406852.36 | F40: =F38+F39 -> 495439.36 | G40: =G38+G39 -> 588549.97 | H40: =H38+H39 -> 686557.55 | I40: =I38+I39 -> 789881.38 | ... K40: =K38+K39 -> 1014423.6
A42: Debt Service Coverage Ratio | B42: =IF(B32=0,0,B28/B32) -> 1.4239615 | C42: =IF(C32=0,0,C28/C32) -> 3.4203248 | D42: =IF(D32=0,0,D28/D32) -> 4.1884768 | E42: =IF(E32=0,0,E28/E32) -> 5.6631635 | F42: =IF(F32=0,0,F28/F32) -> 6.3728802 | G42: =IF(G32=0,0,G28/G32) -> 6.6472405 | H42: =IF(H32=0,0,H28/H32) -> 6.9442465 | I42: =IF(I32=0,0,I28/I32) -> 7.2666818 | ... K42: =IF(K32=0,0,K28/K32) -> 8.0009655
A43: Target: >1.25x for lender comfort
A45: REVENUE MIX (Year 5)
A46: Ground Lease % | B46: =IF(F14=0,0,F6/F14) -> 0.40831347
A47: CSA % | B47: =IF(F14=0,0,F7/F14) -> 0.29061467
A48: Farm Stand % | B48: =IF(F14=0,0,F8/F14) -> 0.10376515
A49: Value-Added % | B49: =IF(F14=0,0,F9/F14) -> 0.046318595
A50: Workshops % | B50: =IF(F14=0,0,F10/F14) -> 0.11159603
...

Sheet P&L — Optimistic
A1: SOVEREIGN MISFIT FARM — OPTIMISTIC SCENARIO
A2: 10-Year Profit & Loss Projection
B4: 2026 | C4: 2027 | D4: 2028 | E4: 2029 | F4: 2030 | G4: 2031 | H4: 2032 | I4: 2033 | J4: 2034 | K4: 2035 | L4: 10-Yr Total
A5: REVENUE
A6: Ground Lease Revenue | B6: =Assumptions!D20*Assumptions!D18*(1+Assumptions!D19)^0*12 -> 39600 | C6: =Assumptions!D21*Assumptions!D18*(1+Assumptions!D19)^1*12 -> 61182 | D6: =Assumptions!D22*Assumptions!D18*(1+Assumptions!D19)^2*12 -> 77021.34 | E6: =Assumptions!D23*(1-Assumptions!D24)*Assumptions!D18*(1+Assumptions!D19)^3*12 -> 84813.099 | F6: =Assumptions!D23*(1-Assumptions!D24)*Assumptions!D18*(1+Assumptions!D19)^4*12 -> 87357.492 | G6: =Assumptions!D23*(1-Assumptions!D24)*Assumptions!D18*(1+Assumptions!D19)^5*12 -> 89978.217 | H6: =Assumptions!D23*(1-Assumptions!D24)*Assumptions!D18*(1+Assumptions!D19)^6*12 -> 92677.563 | I6: =Assumptions!D23*(1-Assumptions!D24)*Assumptions!D18*(1+Assumptions!D19)^7*12 -> 95457.89 | J6: =Assumptions!D23*(1-Assumptions!D24)*Assumptions!D18*(1+Assumptions!D19)^8*12 -> 98321.627 | K6: =Assumptions!D23*(1-Assumptions!D24)*Assumptions!D18*(1+Assumptions!D19)^9*12 -> 101271.28 | L6: =SUM(B6:K6) -> 827680.5
A7: CSA Subscriptions | B7: =(Assumptions!D27)*(Assumptions!D29*(1+Assumptions!D30)^0) -> 28000 | C7: =(Assumptions!D27+(Assumptions!D28-Assumptions!D27)*1/4)*(Assumptions!D29*(1+Assumptions!D30)^1) -> 40040 | D7: =(Assumptions!D27+(Assumptions!D28-Assumptions!D27)*2/4)*(Assumptions!D29*(1+Assumptions!D30)^2) -> 52998.4 | E7: =(Assumptions!D27+(Assumptions!D28-Assumptions!D27)*3/4)*(Assumptions!D29*(1+Assumptions!D30)^3) -> 66929.408 | F7: =(Assumptions!D28)*(Assumptions!D29*(1+Assumptions!D30)^4) -> 81890.099 | G7: =(Assumptions!D28)*(Assumptions!D29*(1+Assumptions!D30)^5) -> 85165.703 | H7: =(Assumptions!D28)*(Assumptions!D29*(1+Assumptions!D30)^6) -> 88572.331 | I7: =(Assumptions!D28)*(Assumptions!D29*(1+Assumptions!D30)^7) -> 92115.225 | J7: =(Assumptions!D28)*(Assumptions!D29*(1+Assumptions!D30)^8) -> 95799.834 | K7: =(Assumptions!D28)*(Assumptions!D29*(1+Assumptions!D30)^9) -> 99631.827 | L7: =SUM(B7:K7) -> 731142.83
A8: Farm Stand Sales | B8: =Assumptions!D31*(1+Assumptions!D32)^0*Assumptions!D33 -> 22400 | C8: =Assumptions!D31*(1+Assumptions!D32)^1*Assumptions!D33 -> 24640 | D8: =Assumptions!D31*(1+Assumptions!D32)^2*Assumptions!D33 -> 27104 | E8: =Assumptions!D31*(1+Assumptions!D32)^3*Assumptions!D33 -> 29814.4 | F8: =Assumptions!D31*(1+Assumptions!D32)^4*Assumptions!D33 -> 32795.84 | G8: =Assumptions!D31*(1+Assumptions!D32)^5*Assumptions!D33 -> 36075.424 | H8: =Assumptions!D31*(1+Assumptions!D32)^6*Assumptions!D33 -> 39682.966 | I8: =Assumptions!D31*(1+Assumptions!D32)^7*Assumptions!D33 -> 43651.263 | J8: =Assumptions!D31*(1+Assumptions!D32)^8*Assumptions!D33 -> 48016.389 | K8: =Assumptions!D31*(1+Assumptions!D32)^9*Assumptions!D33 -> 52818.028 | L8: =SUM(B8:K8) -> 356998.31
A9: Value-Added Products | B9: =Assumptions!D34*(1+Assumptions!D35)^0 -> 8000 | C9: =Assumptions!D34*(1+Assumptions!D35)^1 -> 9600 | D9: =Assumptions!D34*(1+Assumptions!D35)^2 -> 11520 | E9: =Assumptions!D34*(1+Assumptions!D35)^3 -> 13824 | F9: =Assumptions!D34*(1+Assumptions!D35)^4 -> 16588.8 | G9: =Assumptions!D34*(1+Assumptions!D35)^5 -> 19906.56 | H9: =Assumptions!D34*(1+Assumptions!D35)^6 -> 23887.872 | I9: =Assumptions!D34*(1+Assumptions!D35)^7 -> 28665.446 | J9: =Assumptions!D34*(1+Assumptions!D35)^8 -> 34398.536 | K9: =Assumptions!D34*(1+Assumptions!D35)^9 -> 41278.243 | L9: =SUM(B9:K9) -> 207669.46
A10: Workshops & Classes | B10: =(Assumptions!D38)*Assumptions!D40*(Assumptions!D41*(1+Assumptions!D42)^0) -> 16875 | C10: =(Assumptions!D38+(Assumptions!D39-Assumptions!D38)*1/3)*Assumptions!D40*(Assumptions!D41*(1+Assumptions!D42)^1) -> 25492.5 | D10: =(Assumptions!D38+(Assumptions!D39-Assumptions!D38)*2/3)*Assumptions!D40*(Assumptions!D41*(1+Assumptions!D42)^2) -> 34611.863 | E10: =(Assumptions!D39)*Assumptions!D40*(Assumptions!D41*(1+Assumptions!D42)^3) -> 44255.444 | F10: =(Assumptions!D39)*Assumptions!D40*(Assumptions!D41*(1+Assumptions!D42)^4) -> 45583.107 | G10: =(Assumptions!D39)*Assumptions!D40*(Assumptions!D41*(1+Assumptions!D42)^5) -> 46950.6 | H10: =(Assumptions!D39)*Assumptions!D40*(Assumptions!D41*(1+Assumptions!D42)^6) -> 48359.118 | I10: =(Assumptions!D39)*Assumptions!D40*(Assumptions!D41*(1+Assumptions!D42)^7) -> 49809.892 | J10: =(Assumptions!D39)*Assumptions!D40*(Assumptions!D41*(1+Assumptions!D42)^8) -> 51304.188 | K10: =(Assumptions!D39)*Assumptions!D40*(Assumptions!D41*(1+Assumptions!D42)^9) -> 52843.314 | L10: =SUM(B10:K10) -> 416085.02
A11: Farm Tours & Agritourism | B11: =Assumptions!D43*(1+Assumptions!D44)^0 -> 3000 | C11: =Assumptions!D43*(1+Assumptions!D44)^1 -> 3600 | D11: =Assumptions!D43*(1+Assumptions!D44)^2 -> 4320 | E11: =Assumptions!D43*(1+Assumptions!D44)^3 -> 5184 | F11: =Assumptions!D43*(1+Assumptions!D44)^4 -> 6220.8 | G11: =Assumptions!D43*(1+Assumptions!D44)^5 -> 7464.96 | H11: =Assumptions!D43*(1+Assumptions!D44)^6 -> 8957.952 | I11: =Assumptions!D43*(1+Assumptions!D44)^7 -> 10749.542 | J11: =Assumptions!D43*(1+Assumptions!D44)^8 -> 12899.451 | K11: =Assumptions!D43*(1+Assumptions!D44)^9 -> 15479.341 | L11: =SUM(B11:K11) -> 77876.046
A12: Community Kitchen Rental | B12: 0 | C12: =Assumptions!D45*Assumptions!D46*(1+Assumptions!D42)^1 -> 6180 | D12: =Assumptions!D45*Assumptions!D46*(1+Assumptions!D42)^2 -> 6365.4 | E12: =Assumptions!D45*Assumptions!D46*(1+Assumptions!D42)^3 -> 6556.362 | F12: =Assumptions!D45*Assumptions!D46*(1+Assumptions!D42)^4 -> 6753.0529 | G12: =Assumptions!D45*Assumptions!D46*(1+Assumptions!D42)^5 -> 6955.6444 | H12: =Assumptions!D45*Assumptions!D46*(1+Assumptions!D42)^6 -> 7164.3138 | I12: =Assumptions!D45*Assumptions!D46*(1+Assumptions!D42)^7 -> 7379.2432 | J12: =Assumptions!D45*Assumptions!D46*(1+Assumptions!D42)^8 -> 7600.6205 | K12: =Assumptions!D45*Assumptions!D46*(1+Assumptions!D42)^9 -> 7828.6391 | L12: =SUM(B12:K12) -> 62783.276
A14: TOTAL REVENUE | B14: =SUM(B6:B12) -> 117875 | C14: =SUM(C6:C12) -> 170734.5 | D14: =SUM(D6:D12) -> 213941 | E14: =SUM(E6:E12) -> 251376.71 | F14: =SUM(F6:F12) -> 277189.19 | G14: =SUM(G6:G12) -> 292497.11 | H14: =SUM(H6:H12) -> 309302.12 | I14: =SUM(I6:I12) -> 327828.5 | ... L14: =SUM(L6:L12) -> 2680235.4
A16: OPERATING EXPENSES
A17: Property Tax | B17: =Assumptions!D49*(1+Assumptions!D59)^0 -> 0 | C17: =Assumptions!D49*(1+Assumptions!D59)^1 -> 0 | D17: =Assumptions!D49*(1+Assumptions!D59)^2 -> 0 | E17: =Assumptions!D49*(1+Assumptions!D59)^3 -> 0 | F17: =Assumptions!D49*(1+Assumptions!D59)^4 -> 0 | G17: =Assumptions!D49*(1+Assumptions!D59)^5 -> 0 | H17: =Assumptions!D49*(1+Assumptions!D59)^6 -> 0 | I17: =Assumptions!D49*(1+Assumptions!D59)^7 -> 0 | J17: =Assumptions!D49*(1+Assumptions!D59)^8 -> 0 | K17: =Assumptions!D49*(1+Assumptions!D59)^9 -> 0 | L17: =SUM(B17:K17) -> 0
A18: Property Insurance | B18: =Assumptions!D50*(1+Assumptions!D59)^0 -> 6000 | C18: =Assumptions!D50*(1+Assumptions!D59)^1 -> 6180 | D18: =Assumptions!D50*(1+Assumptions!D59)^2 -> 6365.4 | E18: =Assumptions!D50*(1+Assumptions!D59)^3 -> 6556.362 | F18: =Assumptions!D50*(1+Assumptions!D59)^4 -> 6753.0529 | G18: =Assumptions!D50*(1+Assumptions!D59)^5 -> 6955.6444 | H18: =Assumptions!D50*(1+Assumptions!D59)^6 -> 7164.3138 | I18: =Assumptions!D50*(1+Assumptions!D59)^7 -> 7379.2432 | J18: =Assumptions!D50*(1+Assumptions!D59)^8 -> 7600.6205 | K18: =Assumptions!D50*(1+Assumptions!D59)^9 -> 7828.6391 | L18: =SUM(B18:K18) -> 68783.276
A19: Utilities (Common Areas) | B19: =Assumptions!D51*(1+Assumptions!D59)^0 -> 4500 | C19: =Assumptions!D51*(1+Assumptions!D59)^1 -> 4635 | D19: =Assumptions!D51*(1+Assumptions!D59)^2 -> 4774.05 | E19: =Assumptions!D51*(1+Assumptions!D59)^3 -> 4917.2715 | F19: =Assumptions!D51*(1+Assumptions!D59)^4 -> 5064.7896 | G19: =Assumptions!D51*(1+Assumptions!D59)^5 -> 5216.7333 | H19: =Assumptions!D51*(1+Assumptions!D59)^6 -> 5373.2353 | I19: =Assumptions!D51*(1+Assumptions!D59)^7 -> 5534.4324 | J19: =Assumptions!D51*(1+Assumptions!D59)^8 -> 5700.4654 | K19: =Assumptions!D51*(1+Assumptions!D59)^9 -> 5871.4793 | L19: =SUM(B19:K19) -> 51587.457
A20: Farm Operating Costs | B20: =Assumptions!D53*(1+Assumptions!D54)^0 -> 18000 | C20: =Assumptions!D53*(1+Assumptions!D54)^1 -> 19260 | D20: =Assumptions!D53*(1+Assumptions!D54)^2 -> 20608.2 | E20: =Assumptions!D53*(1+Assumptions!D54)^3 -> 22050.774 | F20: =Assumptions!D53*(1+Assumptions!D54)^4 -> 23594.328 | G20: =Assumptions!D53*(1+Assumptions!D54)^5 -> 25245.931 | H20: =Assumptions!D53*(1+Assumptions!D54)^6 -> 27013.146 | I20: =Assumptions!D53*(1+Assumptions!D54)^7 -> 28904.067 | J20: =Assumptions!D53*(1+Assumptions!D54)^8 -> 30927.351 | K20: =Assumptions!D53*(1+Assumptions!D54)^9 -> 33092.266 | L20: =SUM(B20:K20) -> 248696.06
A21: Admin / Legal / Accounting | B21: =Assumptions!D55*(1+Assumptions!D59)^0 -> 5000 | C21: =Assumptions!D55*(1+Assumptions!D59)^1 -> 5150 | D21: =Assumptions!D55*(1+Assumptions!D59)^2 -> 5304.5 | E21: =Assumptions!D55*(1+Assumptions!D59)^3 -> 5463.635 | F21: =Assumptions!D55*(1+Assumptions!D59)^4 -> 5627.5441 | G21: =Assumptions!D55*(1+Assumptions!D59)^5 -> 5796.3704 | H21: =Assumptions!D55*(1+Assumptions!D59)^6 -> 5970.2615 | I21: =Assumptions!D55*(1+Assumptions!D59)^7 -> 6149.3693 | J21: =Assumptions!D55*(1+Assumptions!D59)^8 -> 6333.8504 | K21: =Assumptions!D55*(1+Assumptions!D59)^9 -> 6523.8659 | L21: =SUM(B21:K21) -> 57319.397
A22: Marketing & Outreach | B22: =Assumptions!D56*(1+Assumptions!D59)^0 -> 4000 | C22: =Assumptions!D56*(1+Assumptions!D59)^1 -> 4120 | D22: =Assumptions!D56*(1+Assumptions!D59)^2 -> 4243.6 | E22: =Assumptions!D56*(1+Assumptions!D59)^3 -> 4370.908 | F22: =Assumptions!D56*(1+Assumptions!D59)^4 -> 4502.0352 | G22: =Assumptions!D56*(1+Assumptions!D59)^5 -> 4637.0963 | H22: =Assumptions!D56*(1+Assumptions!D59)^6 -> 4776.2092 | I22: =Assumptions!D56*(1+Assumptions!D59)^7 -> 4919.4955 | J22: =Assumptions!D56*(1+Assumptions!D59)^8 -> 5067.0803 | K22: =Assumptions!D56*(1+Assumptions!D59)^9 -> 5219.0927 | L22: =SUM(B22:K22) -> 45855.517
A23: Community Coordinator | B23: =Assumptions!D57*(1+Assumptions!D59)^0 -> 18000 | C23: =Assumptions!D57*(1+Assumptions!D59)^1 -> 18540 | D23: =Assumptions!D58*(1+Assumptions!D59)^2 -> 33948.8 | E23: =Assumptions!D58*(1+Assumptions!D59)^3 -> 34967.264 | F23: =Assumptions!D58*(1+Assumptions!D59)^4 -> 36016.282 | G23: =Assumptions!D58*(1+Assumptions!D59)^5 -> 37096.77 | H23: =Assumptions!D58*(1+Assumptions!D59)^6 -> 38209.673 | I23: =Assumptions!D58*(1+Assumptions!D59)^7 -> 39355.964 | J23: =Assumptions!D58*(1+Assumptions!D59)^8 -> 40536.643 | K23: =Assumptions!D58*(1+Assumptions!D59)^9 -> 41752.742 | L23: =SUM(B23:K23) -> 338424.14
A24: Maintenance Reserve | B24: =B14*Assumptions!D52 -> 5893.75 | C24: =C14*Assumptions!D52 -> 8536.725 | D24: =D14*Assumptions!D52 -> 10697.05 | E24: =E14*Assumptions!D52 -> 12568.836 | F24: =F14*Assumptions!D52 -> 13859.46 | G24: =G14*Assumptions!D52 -> 14624.855 | H24: =H14*Assumptions!D52 -> 15465.106 | I24: =I14*Assumptions!D52 -> 16391.425 | J24: =J14*Assumptions!D52 -> 17417.032 | K24: =K14*Assumptions!D52 -> 18557.533 | L24: =SUM(B24:K24) -> 134011.77
A26: TOTAL OPERATING EXPENSES | B26: =SUM(B17:B24) -> 61393.75 | C26: =SUM(C17:C24) -> 66421.725 | D26: =SUM(D17:D24) -> 85941.6 | E26: =SUM(E17:E24) -> 90895.05 | F26: =SUM(F17:F24) -> 95417.491 | G26: =SUM(G17:G24) -> 99573.401 | H26: =SUM(H17:H24) -> 103971.95 | I26: =SUM(I17:I24) -> 108634 | ... L26: =SUM(L17:L24) -> 944677.62
A28: OPERATING INCOME (EBITDA) | B28: =B14-B26 -> 56481.25 | C28: =C14-C26 -> 104312.77 | D28: =D14-D26 -> 127999.4 | E28: =E14-E26 -> 160481.66 | F28: =F14-F26 -> 181771.7 | G28: =G14-G26 -> 192923.71 | H28: =H14-H26 -> 205330.17 | I28: =I14-I26 -> 219194.51 | ... L28: =L14-L26 -> 1735557.8
A29: Operating Margin | B29: =IF(B14=0,0,B28/B14) -> 0.47916225 | C29: =IF(C14=0,0,C28/C14) -> 0.61096483 | D29: =IF(D14=0,0,D28/D14) -> 0.59829299 | E29: =IF(E14=0,0,E28/E14) -> 0.63841102 | F29: =IF(F14=0,0,F28/F14) -> 0.65576763 | G29: =IF(G14=0,0,G28/G14) -> 0.65957475 | H29: =IF(H14=0,0,H28/H14) -> 0.66384987 | I29: =IF(I14=0,0,I28/I14) -> 0.66862553 | ... L29: =IF(L14=0,0,L28/L14) -> 0.64753932
A31: DEBT SERVICE
A32: Annual Loan Payment | B32: =Assumptions!D98 -> 12155.7 | C32: =Assumptions!D98 -> 12155.7 | D32: =Assumptions!D98 -> 12155.7 | E32: =Assumptions!D98 -> 12155.7 | F32: =Assumptions!D98 -> 12155.7 | G32: =Assumptions!D98 -> 12155.7 | H32: =Assumptions!D98 -> 12155.7 | I32: =Assumptions!D98 -> 12155.7 | J32: =Assumptions!D98 -> 12155.7 | K32: =Assumptions!D98 -> 12155.7 | L32: =SUM(B32:K32) -> 121557
A34: NET INCOME (after debt service) | B34: =B28-B32 -> 44325.55 | C34: =C28-C32 -> 92157.075 | D34: =D28-D32 -> 115843.7 | E34: =E28-E32 -> 148325.96 | F34: =F28-F32 -> 169616 | G34: =G28-G32 -> 180768.01 | H34: =H28-H32 -> 193174.47 | I34: =I28-I32 -> 207038.81 | ... L34: =L28-L32 -> 1614000.8
A35: Net Margin | B35: =IF(B14=0,0,B34/B14) -> 0.3760386 | C35: =IF(C14=0,0,C34/C14) -> 0.53976833 | D35: =IF(D14=0,0,D34/D14) -> 0.54147499 | E35: =IF(E14=0,0,E34/E14) -> 0.59005451 | F35: =IF(F14=0,0,F34/F14) -> 0.61191419 | G35: =IF(G14=0,0,G34/G14) -> 0.61801639 | H35: =IF(H14=0,0,H34/H14) -> 0.62454946 | I35: =IF(I14=0,0,I34/I14) -> 0.63154608 | ... L35: =IF(L14=0,0,L34/L14) -> 0.60218621
A37: CASH FLOW & RESERVES
A38: Beginning Cash Balance | B38: =Assumptions!D92 -> 470000 | C38: =B40 -> 514325.55 | D38: =C40 -> 606482.63 | E38: =D40 -> 722326.33 | F38: =E40 -> 870652.29 | G38: =F40 -> 1040268.3 | H38: =G40 -> 1221036.3 | I38: =H40 -> 1414210.8 | J38: =I40 -> 1621249.6 | K38: =J40 -> 1843851.5
A39: Net Cash Flow (this year) | B39: =B34 -> 44325.55 | C39: =C34 -> 92157.075 | D39: =D34 -> 115843.7 | E39: =E34 -> 148325.96 | F39: =F34 -> 169616 | G39: =G34 -> 180768.01 | H39: =H34 -> 193174.47 | I39: =I34 -> 207038.81 | ... K39: =K34 -> 240149.35
A40: Ending Cash Balance | B40: =B38+B39 -> 514325.55 | C40: =C38+C39 -> 606482.63 | D40: =D38+D39 -> 722326.33 | E40: =E38+E39 -> 870652.29 | F40: =F38+F39 -> 1040268.3 | G40: =G38+G39 -> 1221036.3 | H40: =H38+H39 -> 1414210.8 | I40: =I38+I39 -> 1621249.6 | ... K40: =K38+K39 -> 2084000.8
A42: Debt Service Coverage Ratio | B42: =IF(B32=0,0,B28/B32) -> 4.6464828 | C42: =IF(C32=0,0,C28/C32) -> 8.5813879 | D42: =IF(D32=0,0,D28/D32) -> 10.52999 | E42: =IF(E32=0,0,E28/E32) -> 13.202174 | F42: =IF(F32=0,0,F28/F32) -> 14.953619 | G42: =IF(G32=0,0,G28/G32) -> 15.871049 | H42: =IF(H32=0,0,H28/H32) -> 16.891678 | I42: =IF(I32=0,0,I28/I32) -> 18.032241 | ... K42: =IF(K32=0,0,K28/K32) -> 20.756111
A43: Target: >1.25x for lender comfort
A45: REVENUE MIX (Year 5)
A46: Ground Lease % | B46: =IF(F14=0,0,F6/F14) -> 0.31515476
A47: CSA % | B47: =IF(F14=0,0,F7/F14) -> 0.29543035
A48: Farm Stand % | B48: =IF(F14=0,0,F8/F14) -> 0.11831572
A49: Value-Added % | B49: =IF(F14=0,0,F9/F14) -> 0.05984649
A50: Workshops % | B50: =IF(F14=0,0,F10/F14) -> 0.16444763
...

Sheet Dashboard
A1: SOVEREIGN MISFIT FARM — SCENARIO COMPARISON
A2: Key Metrics Dashboard
A4: Metric | B4: Conservative | C4: Moderate | D4: Optimistic | F4: Notes
A5: PHASED CAPITAL STRUCTURE
A6: Phase 1 Capital Need (Land + Site) | B6: =Assumptions!B66 -> 385000 | C6: =Assumptions!C66 -> 312000 | D6: =Assumptions!D66 -> 240000 | F6: Year 0-1
A7: Phase 2 Capital Need (Hall + Farm) | B7: =Assumptions!B71 -> 310000 | C7: =Assumptions!C71 -> 250000 | D7: =Assumptions!D71 -> 190000 | F7: Year 2-3
A8: Total Capital Need | B8: =Assumptions!B73 -> 695000 | C8: =Assumptions!C73 -> 562000 | D8: =Assumptions!D73 -> 430000 | F8: All phases
A9: Total Funding Available | B9: =Assumptions!B91 -> 405000 | C9: =Assumptions!C91 -> 542500 | D9: =Assumptions!D91 -> 710000 | F9: All sources stacked
A10: Phase 1 Surplus / Gap | B10: =Assumptions!B92 -> 20000 | C10: =Assumptions!C92 -> 230500 | D10: =Assumptions!D92 -> 470000 | F10: Critical: must be positive
A11: Total Project Surplus / Gap | B11: =Assumptions!B93 -> -290000 | C11: =Assumptions!C93 -> -19500 | D11: =Assumptions!D93 -> 280000
A12: YEAR 1 PERFORMANCE
A13: Total Revenue | B13: ='P&L — Conservative'!B14 -> 48600 | C13: ='P&L — Moderate'!B14 -> 78700 | D13: ='P&L — Optimistic'!B14 -> 117875
A14: Total Expenses | B14: ='P&L — Conservative'!B26 -> 43888 | C14: ='P&L — Moderate'!B26 -> 55222 | D14: ='P&L — Optimistic'!B26 -> 61393.75
A15: Operating Income | B15: ='P&L — Conservative'!B28 -> 4712 | C15: ='P&L — Moderate'!B28 -> 23478 | D15: ='P&L — Optimistic'!B28 -> 56481.25
A16: Net Income (after debt) | B16: ='P&L — Conservative'!B34 -> -18207.833 | C16: ='P&L — Moderate'!B34 -> 6990.1944 | D16: ='P&L — Optimistic'!B34 -> 44325.55
A17: DSCR | B17: ='P&L — Conservative'!B42 -> 0.20558614 | C17: ='P&L — Moderate'!B42 -> 1.4239615 | D17: ='P&L — Optimistic'!B42 -> 4.6464828
A19: YEAR 5 (STABILIZED)
